Workbook

Sheet Conferences
A1: # | B1: Acronym | C1: Year | D1: Edition | E1: Full Title | F1: Category | G1: Relevance | H1: Priority | I1: Publisher | J1: Indexing | K1: Cost (as verified) | L1: Fee | M1: Currency | N1: Abstract Deadline | O1: Submission Deadline | P1: Notification | Q1: Camera-Ready | R1: Registration Deadline | S1: Event Dates | T1: Event Start | U1: Event End | V1: Location / Venue | W1: Format | X1: Days to Deadline | Y1: Submission Status | Z1: Submission System | AA1: Paper Length | AB1: Website | AC1: Available Resources | AD1: Contact | AE1: Last Verified | AF1: Verification Notes | AG1: Added to List
A2: 1 | B2: CSAM | C2: 2026 | D2: XI | E2: XI International Scientific Conference “Computer Science and Applied Mathematics” | F2: Conference | G2: High | H2: =IF($G2="High",1,IF($G2="Mediocre",2,3)) -> 1 | I2: Academic Journal | J2: Conference collection; best presentations forwarded to Bulletin of KazNU (Mathematics, Mechanics, Computer Science), Problems of Computer Science (Siberian Branch RAS) and other Scopus / Web of Science journals | K2: Not published on the site | O2: 46280 | P2: 46295 | Q2: 46305 | S2: 07–11 Oct 2026 | T2: 46302 | U2: 46306 | V2: Al-Farabi Kazakh National University & Institute of Information and Computational Technologies, Al-Farabi Ave 71, Almaty, Kazakhstan | W2: In-person | X2: =IF(O2="","",INT(O2)-TODAY()) -> 11 | Y2: =IF($G2="Finished","Expired",IF(AND(O2<>"",INT(O2)>=TODAY()),IF(INT(O2)-TODAY()<=30,"Open - closing soon","Open"),IF(AND(T2<>"",U2<>"",INT(T2)<=TODAY(),INT(U2)>=TODAY()),"Event in progress",IF(AND(O2="",R2<>"",INT(R2)>=TODAY()),"Registration due",IF(AND(O2="",U2<>"",INT(U2)>=TODAY()),"Deadline not published",IF(AND(O2<>"",Q2<>"",INT(Q2)>=TODAY()),"Camera-ready due",IF(AND(O2<>"",R2<>"",INT(R2)>=TODAY()),"Registration due",IF(AND(U2<>"",INT(U2)>=TODAY()),"Submissions closed - event ahead","Expired")))))))) -> Open - closing soon | Z2: Google Form (forms.gle/rysdTmshMxarg2je7); separate registration form forms.gle/ZHTzheKQF4qgrDVu8 | AA2: Not published on the site | AB2: https://csam.kaznu.kz/en | AC2: Website; Submission; Registration | AD2: opcs2026sc@gmail.com; +7 708-354-21-65, +7 702-322-29-99, +7 707-933-88-90, +7 708-961-48-78, +7 707-375-22-96 (organising committee Mon-Fri 09:00-18:00, Almaty time UTC+6) | AE2: 46269 | AF2: RE-READ 04.09.2026, ALL THREE DEADLINES CONFIRMED on the Important Dates block: submission 15.09.2026 (11 days out), notification 30.09.2026, camera-ready 10.10.2026; event 07-11.10.2026. ADDED the organising-committee e-mail opcs2026sc@gmail.com and the four further phone numbers, and separated the two Google Forms: papers go to forms.gle/rysdTmshMxarg2je7, participant registration to forms.gle/ZHTzheKQF4qgrDVu8. The "Microsoft CMT" line in the page footer is CMT's standard acknowledgement boilerplate, NOT the submission route. The footer phone "+7 707 123 4567" is placeholder text; the Contacts page carries the real numbers. Still no fee published and no online-participation option. XI International Scientific Conference "Computer Science and Applied Mathematics", also styled the 11th International Conference "Informatics and Applied Mathematics"; organised by the Institute of Information and Computational Technologies, Al-Farabi KazNU, Lublin University of Technology and Turan University. Four tracks. NOT a CEUR venue - CEUR Vol-3922 is a different conference (IAM, Guelma, Algeria). | AG2: 46269
A3: 2 | B3: AISTDS | C3: 2026 | D3: 10th (inferred) | E3: Applied Information Systems and Technologies in the Digital Society | F3: Workshop | G3: High | H3: =IF($G3="High",1,IF($G3="Mediocre",2,3)) -> 1 | I3: CEUR.org | J3: DBLP, Scopus, Google Scholar | K3: 500 UAH registration fee (covers participation, publication, programme and the electronic proceedings) | L3: 500 | M3: UAH | O3: 46292 | R3: 46292 | S3: 01 Oct 2026, 10:00 | T3: 46296 | U3: 46296 | V3: Department of Applied Information Systems, Faculty of Information Technology, Taras Shevchenko National University of Kyiv, 24 Bohdan Hawrylyshyn Str, 4th floor, room 401, Kyiv, Ukraine | W3: Online (Zoom) | X3: =IF(O3="","",INT(O3)-TODAY()) -> 23 | Y3: =IF($G3="Finished","Expired",IF(AND(O3<>"",INT(O3)>=TODAY()),IF(INT(O3)-TODAY()<=30,"Open - closing soon","Open"),IF(AND(T3<>"",U3<>"",INT(T3)<=TODAY(),INT(U3)>=TODAY()),"Event in progress",IF(AND(O3="",R3<>"",INT(R3)>=TODAY()),"Registration due",IF(AND(O3="",U3<>"",INT(U3)>=TODAY()),"Deadline not published",IF(AND(O3<>"",Q3<>"",INT(Q3)>=TODAY()),"Camera-ready due",IF(AND(O3<>"",R3<>"",INT(R3)>=TODAY()),"Registration due",IF(AND(U3<>"",INT(U3)>=TODAY()),"Submissions closed - event ahead","Expired")))))))) -> Open - closing soon | Z3: E-mail to the organising committee | AA3: At least 10 pages, English, PDF, Microsoft Word CEUR template; max 4 authors (5 by exception) | AB3: https://aistis.knu.ua/how-to-submit/ | AC3: Website | AD3: aistis.conference@gmail.com; +38 (044) 481 44 82 | AE3: 46269 | AF3: OPEN - 23 days to the deadline. Submission AND payment both 27.09.2026, confirmed on /how-to-submit/ and /terms-and-fees/; 500 UAH covers participation, publication, the programme and the electronic collection. FORMAT CORRECTED from "Not stated": the home page says the conference is "held online with the use of Zoom platform". VENUE made specific (Dept of Applied Information Systems, 24 Bohdan Hawrylyshyn Str, room 401) and the committee phone added. EDITION FILLED as 10th by inference, not by statement: CEUR shows AISTDS 2024 = 8th (Vol-3942, 01.10.2024) and AISTDS 2025 = 9th (Vol-4133, 01.10.2025), so 2026 is the tenth - confirm with the organisers. Notification and camera-ready are still given only as "October 2026", with no day. Papers reviewed by at least two independent reviewers. Payment is styled a charitable contribution to Yevhenii Topolskov. | AG3: 45730
A4: 3 | B4: ATRIC | C4: 2026 | D4: — | E4: International Conference on Advanced Trends in Radioelectronics and Infocommunications | F4: Workshop | G4: High | H4: =IF($G4="High",1,IF($G4="Mediocre",2,3)) -> 1 | I4: Conference website (electronic proceedings) | J4: Not indexed - proceedings recommended by the Organising Committee are published electronically on the conference website after the event, following independent review | K4: Free — "The conference is free of organizational fees" (accommodation and meals at participants' own cost) | L4: 0 | M4: — | O4: 46295 | P4: 46305 | R4: 46295 | S4: 15–17 Oct 2026 | T4: 46310 | U4: 46312 | V4: Lviv Polytechnic National University, S. Bandera Str., building 12, Lviv 79013, Ukraine (organising committee: Department of Software and Hardware Systems of Infocommunications, Professorska Str. 2, Lviv 79013) | W4: Hybrid (on-site and videoconference) | X4: =IF(O4="","",INT(O4)-TODAY()) -> 26 | Y4: =IF($G4="Finished","Expired",IF(AND(O4<>"",INT(O4)>=TODAY()),IF(INT(O4)-TODAY()<=30,"Open - closing soon","Open"),IF(AND(T4<>"",U4<>"",INT(T4)<=TODAY(),INT(U4)>=TODAY()),"Event in progress",IF(AND(O4="",R4<>"",INT(R4)>=TODAY()),"Registration due",IF(AND(O4="",U4<>"",INT(U4)>=TODAY()),"Deadline not published",IF(AND(O4<>"",Q4<>"",INT(Q4)>=TODAY()),"Camera-ready due",IF(AND(O4<>"",R4<>"",INT(R4)>=TODAY()),"Registration due",IF(AND(U4<>"",INT(U4)>=TODAY()),"Submissions closed - event ahead","Expired")))))))) -> Open - closing soon | Z4: Google Forms registration + e-mail | AA4: Abstracts 2-4 full A5 pages, Times New Roman 11pt, line spacing 1.2, margins 1.5 cm all round, Ukrainian or English, MS Word | AB4: https://science.lpnu.ua/atric-2026 | AC4: Website | AD4: atric.conference@lpnu.ua; +38(032)2582156, +380985864516 (conference secretary Ivan Maksymiv) | AE4: 46269 | AF4: OPEN - 26 days out. The dates block reads exactly: 30.09.2026 18:00 submission of applications and the full text of report materials; 10.10.2026 18:00 Organising Committee confirmation of acceptance and inclusion in the programme; 15.10.2026 10:00 opening and plenary session. Event 15-17.10.2026. FREE of organisational fees confirmed on the Organizational Fee page (accommodation and meals at participants' own cost; hotel requests to the committee by 12.10.2026). ADDED the contact block and the full venue. PUBLISHER CORRECTED from "Not specified": there is no external publisher - proceedings appear on the conference site after the event. Working languages Ukrainian and English. Marks the 100th anniversary of the Lviv amateur radio movement, supported by the NGO "Lviv HF Amateur Radio Club". | AG4: 45778
A5: 4 | B5: CITI | C5: 2026 | D5: 4th | E5: The 4th International Conference on “Computer Information Technologies in Industry 4.0” | F5: Workshop | G5: High | H5: =IF($G5="High",1,IF($G5="Mediocre",2,3)) -> 1 | I5: CEUR.org | J5: Scopus (planned) | K5: Free — "Participation and publication are free of charge!" | L5: 0 | M5: — | O5: 46295 | P5: 46316 | Q5: 46325 | S5: 04–06 Nov 2026 | T5: 46330 | U5: 46332 | V5: Ternopil Ivan Puluj National Technical University, Ternopil, Ukraine (hybrid, jointly with Warsaw, Poland) | W5: Hybrid | X5: =IF(O5="","",INT(O5)-TODAY()) -> 26 | Y5: =IF($G5="Finished","Expired",IF(AND(O5<>"",INT(O5)>=TODAY()),IF(INT(O5)-TODAY()<=30,"Open - closing soon","Open"),IF(AND(T5<>"",U5<>"",INT(T5)<=TODAY(),INT(U5)>=TODAY()),"Event in progress",IF(AND(O5="",R5<>"",INT(R5)>=TODAY()),"Registration due",IF(AND(O5="",U5<>"",INT(U5)>=TODAY()),"Deadline not published",IF(AND(O5<>"",Q5<>"",INT(Q5)>=TODAY()),"Camera-ready due",IF(AND(O5<>"",R5<>"",INT(R5)>=TODAY()),"Registration due",IF(AND(U5<>"",INT(U5)>=TODAY()),"Submissions closed - event ahead","Expired")))))))) -> Open - closing soon | Z5: Microsoft CMT (cmt3.research.microsoft.com/CITI2026) | AA5: Regular papers 10-20 full pages, short papers 5-9 full pages; English, proofread; CEUR-ART one-column LibreOffice ODT template with the Libertinus font family (cloud editors and Word/Microsoft365 discouraged); max 5 co-authors; max 2 papers per author; title up to 13 words; references mostly not older than 5-8 years | AB5: https://citi.tntu.edu.ua/ | AC5: Website; Submission; CMT | AD5: citiconf@tntu.edu.ua | AE5: 46269 | AF5: OPEN - 26 days out. Deadlines confirmed verbatim: papers before 30.09.2026, notification on 21.10.2026, camera-ready before 30.10.2026; event 04-06.11.2026. "Participation and publication are free of charge!" confirmed. SUBMISSION SYSTEM CORRECTED: the previous pass recorded EasyChair, but /submission/ names Microsoft CMT at cmt3.research.microsoft.com/CITI2026. PAPER LENGTH AND FORMATTING FILLED IN (were blank) and the contact e-mail added. Venue is hybrid TNTU Ternopil with Warsaw, Poland. Proceedings to CEUR-WS, "planned to be indexed in Scopus". | AG5: 45608
A6: 5 | B6: BAITmp | C6: 2026 | D6: 3rd | E6: The 3rd International Workshop on Bioinformatics and Applied Information Technologies for Medical Purpose | F6: Workshop | G6: High | H6: =IF($G6="High",1,IF($G6="Mediocre",2,3)) -> 1 | I6: CEUR.org | J6: Scopus & Web of Science (planned) | K6: Free — "Participate for FREE ₴0" | L6: 0 | M6: — | O6: 46296 | P6: 46327 | Q6: 46334 | S6: 11–13 Nov 2026 | T6: 46337 | U6: 46339 | V6: Mohammed VI Polytechnic University, Benguerir, Morocco & Ternopil Ivan Puluj NTU, Ukraine | W6: Online presentations | X6: =IF(O6="","",INT(O6)-TODAY()) -> 27 | Y6: =IF($G6="Finished","Expired",IF(AND(O6<>"",INT(O6)>=TODAY()),IF(INT(O6)-TODAY()<=30,"Open - closing soon","Open"),IF(AND(T6<>"",U6<>"",INT(T6)<=TODAY(),INT(U6)>=TODAY()),"Event in progress",IF(AND(O6="",R6<>"",INT(R6)>=TODAY()),"Registration due",IF(AND(O6="",U6<>"",INT(U6)>=TODAY()),"Deadline not published",IF(AND(O6<>"",Q6<>"",INT(Q6)>=TODAY()),"Camera-ready due",IF(AND(O6<>"",R6<>"",INT(R6)>=TODAY()),"Registration due",IF(AND(U6<>"",INT(U6)>=TODAY()),"Submissions closed - event ahead","Expired")))))))) -> Open - closing soon | Z6: EasyChair (easychair.org/conferences?conf=bait2025 - the link still carries the 2025 slug) | AA6: Regular papers 10-20 full pages, short papers 5-9 full pages; English; CEUR-ART one-column LibreOffice ODT template with the Libertinus font family; PDF plus ODT/LaTeX source; max 5 co-authors; max 2 papers per author; each paper needs at least one author with at least 5 papers in DBLP; signed Author Agreement required | AB6: https://bait.tntu.edu.ua/ | AC6: Website; Submission; EasyChair | AD6: baitconf@tntu.edu.ua | AE6: 46269 | AF6: OPEN - 27 days out. Deadlines confirmed: paper 01.10.2026, notification 01.11.2026, camera-ready 08.11.2026. Free ("Participate for FREE"). ADDED paper length, formatting, the DBLP condition and the contact e-mail. SUBMISSION SYSTEM identified as EasyChair, but the live link still points at conf=bait2025 - verify with the organisers before submitting. THE SITE CONTRADICTS ITSELF ON THE EVENT DATES, three ways on one page: the banner says "November 16-18, 2026", the dates-box header says "November 12-13, 2026", and "November 11-13, 2026" appears twice in the body. 11-13.11.2026 is the reading kept here because it is the one repeated in the call itself, but confirm with the organisers. Held jointly with Mohammed VI Polytechnic University, Benguerir, Morocco; online presentations; proceedings to CEUR-WS, planned for Scopus and Web of Science. 3rd edition (the site writes "3nd"). | AG6: 45620
A7: 6 | B7: ICTM | C7: 2026 | D7: — | E7: Integrated Computer Technologies in Mechanical Engineering – Synergetic Engineering | F7: Conference + Workshop | G7: High | H7: =IF($G7="High",1,IF($G7="Mediocre",2,3)) -> 1 | I7: Springer.org | J7: Springer Science+Business Media book chapter; partnership option with the journal "Computation"; peer review by at least three scholars; free submission for students and PhD candidates | K7: Not published | O7: 46296 | P7: 46327 | S7: 18–20 Nov 2026 | T7: 46344 | U7: 46346 | V7: National Aerospace University "KhAI", Vadyma Manka st. 17, Kharkiv 61070, Ukraine | W7: Not stated | X7: =IF(O7="","",INT(O7)-TODAY()) -> 27 | Y7: =IF($G7="Finished","Expired",IF(AND(O7<>"",INT(O7)>=TODAY()),IF(INT(O7)-TODAY()<=30,"Open - closing soon","Open"),IF(AND(T7<>"",U7<>"",INT(T7)<=TODAY(),INT(U7)>=TODAY()),"Event in progress",IF(AND(O7="",R7<>"",INT(R7)>=TODAY()),"Registration due",IF(AND(O7="",U7<>"",INT(U7)>=TODAY()),"Deadline not published",IF(AND(O7<>"",Q7<>"",INT(Q7)>=TODAY()),"Camera-ready due",IF(AND(O7<>"",R7<>"",INT(R7)>=TODAY()),"Registration due",IF(AND(U7<>"",INT(U7)>=TODAY()),"Submissions closed - event ahead","Expired")))))))) -> Open - closing soon | Z7: E-mail to the organising committee (no online system; the submission page still shows the 2020 conference dates) | AA7: At least 10 and not more than 12 pages for the Springer book; Springer splnproc template (splnproc1703.zip) | AB7: https://ictm.khai.edu/ | AC7: Website; EasyChair | AD7: ictm2024@khai.edu; +380577884105 (chair Prof. Volodymyr Pavlikov; publication chair Assoc. Prof. Dmytro Kritskiy; secretary Assoc. Prof. Tetiana Starovoit) | AE7: 46269 | AF7: OPEN - 27 days out. Submission 01.10.2026 and notification 01.11.2026 confirmed; event 18-20.11.2026 at Kharkiv, Vadyma Manka st. 17 (the Contacts page still uses the street's former name, Chkalova 17 - same address). ADDED paper length (10-12 pages, Springer template), the publisher detail and the contact block; the site's e-mail is Cloudflare-obfuscated and decodes to ictm2024@khai.edu, an address still carrying the 2024 year. No camera-ready date, no fee and no indexing statement are published for 2026, and the submission page is stale (it still prints "29-30 October 2020"), so treat the submission route as e-mail and confirm with the committee. | AG7: 44779
A8: 7 | B8: DOORS | C8: 2027 | D8: 7th | E8: 7th Edge Computing Workshop | F8: Conference | G8: High | H8: =IF($G8="High",1,IF($G8="Mediocre",2,3)) -> 1 | I8: ACM Digital Library | J8: ACM ICPS; post-proceedings in the Journal of Edge Computing | K8: Not published | O8: 46367 | P8: 46389 | Q8: 46399 | R8: 46467 | S8: 02 Apr 2027 | T8: 46479 | U8: 46479 | V8: Zhytomyr Polytechnic State University, Department of Software Engineering, Zhytomyr, Ukraine | W8: Not stated | X8: =IF(O8="","",INT(O8)-TODAY()) -> 98 | Y8: =IF($G8="Finished","Expired",IF(AND(O8<>"",INT(O8)>=TODAY()),IF(INT(O8)-TODAY()<=30,"Open - closing soon","Open"),IF(AND(T8<>"",U8<>"",INT(T8)<=TODAY(),INT(U8)>=TODAY()),"Event in progress",IF(AND(O8="",R8<>"",INT(R8)>=TODAY()),"Registration due",IF(AND(O8="",U8<>"",INT(U8)>=TODAY()),"Deadline not published",IF(AND(O8<>"",Q8<>"",INT(Q8)>=TODAY()),"Camera-ready due",IF(AND(O8<>"",R8<>"",INT(R8)>=TODAY()),"Registration due",IF(AND(U8<>"",INT(U8)>=TODAY()),"Submissions closed - event ahead","Expired")))))))) -> Open | Z8: HotCRP | AA8: Full papers, at least 10 pages, LaTeX-generated PDF | AB8: https://edge.easyscience.education/2027/ | AC8: Website; Submission | AD8: tetianavakaliuk@acnsci.org; +380-96-065-3099 (Tetiana Vakaliuk) | AE8: 46269 | AF8: All four dates confirmed: submission 11.12.2026, notification 02.01.2027, camera-ready 12.01.2027, registration 21.03.2027; event 02.04.2027. ADDED the venue detail (Zhytomyr Polytechnic State University, Department of Software Engineering) and the chair's contact. Full papers at least 10 pages, LaTeX-generated PDF, submitted through HotCRP. Proceedings published online; selected papers eligible for the Journal of Edge Computing after a secondary review. No fee published. | AG8: 45581
A9: 8 | B9: SCIA | C9: 2027 | D9: — | E9: Scandinavian Conference on Image Analysis | F9: Conference | G9: High | H9: =IF($G9="High",1,IF($G9="Mediocre",2,3)) -> 1 | I9: Springer.org | J9: Springer LNCS | K9: Not published (early-bird registration deadline TBA) | N9: 46446 | O9: 46413 | P9: 46462 | Q9: 46488 | S9: 09–11 Jun 2027 (tutorials & workshops 08 Jun) | T9: 46547 | U9: 46549 | V9: Norwegian University of Science and Technology, Gjøvik, Norway | W9: Not stated | X9: =IF(O9="","",INT(O9)-TODAY()) -> 144 | Y9: =IF($G9="Finished","Expired",IF(AND(O9<>"",INT(O9)>=TODAY()),IF(INT(O9)-TODAY()<=30,"Open - closing soon","Open"),IF(AND(T9<>"",U9<>"",INT(T9)<=TODAY(),INT(U9)>=TODAY()),"Event in progress",IF(AND(O9="",R9<>"",INT(R9)>=TODAY()),"Registration due",IF(AND(O9="",U9<>"",INT(U9)>=TODAY()),"Deadline not published",IF(AND(O9<>"",Q9<>"",INT(Q9)>=TODAY()),"Camera-ready due",IF(AND(O9<>"",R9<>"",INT(R9)>=TODAY()),"Registration due",IF(AND(U9<>"",INT(U9)>=TODAY()),"Submissions closed - event ahead","Expired")))))))) -> Open | Z9: Not stated | AA9: Not published on the site | AB9: https://scia2027.org/ | AC9: Website | AD9: scia2027@idi.ntnu.no | AE9: 46269 | AF9: Dates confirmed and they really are in this order: paper submission opens 01.12.2026 and closes 26.01.2027; the separate ABSTRACT window opens 12.02.2027 and closes 28.02.2027 - the abstract deadline falls AFTER the paper deadline because they are different tracks, so this is not a transcription error. Notification 16.03.2027, camera-ready 11.04.2027. Event 09-11.06.2027 with tutorials and workshops on 08.06.2027, at NTNU Gjovik. ADDED the contact address. Springer LNCS branding is on the site but no page limits, fees or submission-system URL are published yet (early-bird registration still TBA). | AG9: 45674
A10: 9 | B10: IDAACS | C10: 2027 | D10: 14th | E10: The 14th IEEE International Conference on Intelligent Data Acquisition and Advanced Computing Systems: Technology and Applications | F10: Conference | G10: High | H10: =IF($G10="High",1,IF($G10="Mediocre",2,3)) -> 1 | I10: IEEE.org | J10: IEEE Xplore; Scopus, DBLP, WoS CPCI expected | K10: Not published for 2027 | N10: 46446 | O10: 46446 | P10: 46477 | Q10: 46507 | R10: 46538 | S10: 22–25 Sep 2027 | T10: 46652 | U10: 46655 | V10: Hellenic Army Academy, Athens, Greece | W10: Not stated | X10: =IF(O10="","",INT(O10)-TODAY()) -> 177 | Y10: =IF($G10="Finished","Expired",IF(AND(O10<>"",INT(O10)>=TODAY()),IF(INT(O10)-TODAY()<=30,"Open - closing soon","Open"),IF(AND(T10<>"",U10<>"",INT(T10)<=TODAY(),INT(U10)>=TODAY()),"Event in progress",IF(AND(O10="",R10<>"",INT(R10)>=TODAY()),"Registration due",IF(AND(O10="",U10<>"",INT(U10)>=TODAY()),"Deadline not published",IF(AND(O10<>"",Q10<>"",INT(Q10)>=TODAY()),"Camera-ready due",IF(AND(O10<>"",R10<>"",INT(R10)>=TODAY()),"Registration due",IF(AND(U10<>"",INT(U10)>=TODAY()),"Submissions closed - event ahead","Expired")))))))) -> Open | Z10: Microsoft CMT (cmt3.research.microsoft.com/IDAACS2027) | AA10: Not published on the site | AB10: https://www.idaacs.net/2027 | AC10: Website; CAP | AD10: orgcom@idaacs.net | AE10: 46269 | AF10: Dates confirmed: extended-abstract submission 28.02.2027 (this is the only submission deadline the site publishes, which is why the abstract and submission columns carry the same date), notification 31.03.2027, camera-ready 30.04.2027. REGISTRATION refined: early registration runs 02.04-31.05.2027, and late registration OPENS 01.06.2027 - 31.05.2027 is therefore the early-bird cut-off, not an absolute close. Event 22-25.09.2027, Hellenic Army Academy, Athens. Submission through Microsoft CMT. Accepted papers go to the conference proceedings and are submitted to IEEE Xplore; Scopus, DBLP and WoS CPCI expected. No 2027 fee published; no author page limit published yet. | AG10: 45723
A11: 10 | B11: ACIT | C11: 2027 | D11: 17th | E11: IEEE 17th International Conference on Advanced Computer Information Technologies | F11: Conference | G11: High | H11: =IF($G11="High",1,IF($G11="Mediocre",2,3)) -> 1 | I11: IEEE.org | J11: IEEE Xplore; registered Scopus periodical "Proceedings - International Conference on Advanced Computer Information Technologies (ACIT)"; Google Scholar, Web of Science, DBLP, SCImago; Online ISSN 2770-5226, Print ISSN 2770-5218; 2026 acceptance rate 46.92% | K11: Not published for 2027 - the shared Payments page still shows the ACIT'2026 schedule (on-site 350 EUR non-IEEE / 300 EUR IEEE member or PhD student / 250 EUR IEEE PhD student; online 120 / 90 / 70 EUR; accompanying person 200 EUR; free for single-author student papers; +20 EUR per page above 4; one registration covers up to two accepted papers) with payment due 30.06.2026 | M11: EUR | O11: 46481 | P11: 46530 | Q11: 46551 | R11: 46568 | S11: 13–15 Sep 2027 | T11: 46643 | U11: 46645 | V11: Constantine the Philosopher University, Tr. A. Hlinku 1, 949 01 Nitra, Slovakia | W11: Hybrid | X11: =IF(O11="","",INT(O11)-TODAY()) -> 212 | Y11: =IF($G11="Finished","Expired",IF(AND(O11<>"",INT(O11)>=TODAY()),IF(INT(O11)-TODAY()<=30,"Open - closing soon","Open"),IF(AND(T11<>"",U11<>"",INT(T11)<=TODAY(),INT(U11)>=TODAY()),"Event in progress",IF(AND(O11="",R11<>"",INT(R11)>=TODAY()),"Registration due",IF(AND(O11="",U11<>"",INT(U11)>=TODAY()),"Deadline not published",IF(AND(O11<>"",Q11<>"",INT(Q11)>=TODAY()),"Camera-ready due",IF(AND(O11<>"",R11<>"",INT(R11)>=TODAY()),"Registration due",IF(AND(U11<>"",INT(U11)>=TODAY()),"Submissions closed - event ahead","Expired")))))))) -> Open | Z11: Microsoft CMT (cmt3.research.microsoft.com/ACIT2027) | AA11: Final paper 4–10 pages, IEEE Proceedings format, DOC or LaTeX, max 6 co-authors | AB11: https://acit.tech/index.php/acit2027 | AC11: Website; Call for Papers (PDF); CMT | AD11: workshopACIT@gmail.com; +380977761442 (Faculty of Computer Information Technologies, West Ukrainian National University, 8 Oleny Teligy str., Ternopil, Ukraine) | AE11: 46269 | AF11: Dates confirmed on the ACIT'2027 page: paper 04.04.2027, notification 23.05.2027, camera-ready 13.06.2027, online registration AND fee payment 30.06.2027. COST CORRECTED - this was the main error here. The euro figures the tracker carried are the ACIT'2026 schedule: /payments and /venue are shared pages that still describe ACIT'2026 in Zlin, Czech Republic, with payment by 30.06.2026. No 2027 fee has been published, so the numeric Fee cell has been cleared (it read 0, which wrongly implied a free conference). ACIT'2027 itself is in Nitra, Slovakia, hosted by Constantine the Philosopher University, in hybrid format; ignore the Zlin address that the shared pages still show. Papers 4-10 pages, IEEE Proceedings format, max 6 co-authors, through Microsoft CMT. Indexing expanded with both ISSNs and the 2026 acceptance rate. | AG11: 43964
A12: 11 | B12: FedCSIS | C12: 2027 | D12: 22nd | E12: 22nd Conference on Computer Science and Intelligence Systems | F12: Conference | G12: High | H12: =IF($G12="High",1,IF($G12="Mediocre",2,3)) -> 1 | I12: IEEE.org | J12: Annals of Computer Science and Information Systems; IEEE catalogue TBA | K12: TBA — the conference fees page reads "TBA" | O12: 46521 | P12: 46566 | Q12: 46583 | R12: 46599 | S12: 12–15 Sep 2027 | T12: 46642 | U12: 46645 | V12: Gdynia, Poland | W12: Not stated | X12: =IF(O12="","",INT(O12)-TODAY()) -> 252 | Y12: =IF($G12="Finished","Expired",IF(AND(O12<>"",INT(O12)>=TODAY()),IF(INT(O12)-TODAY()<=30,"Open - closing soon","Open"),IF(AND(T12<>"",U12<>"",INT(T12)<=TODAY(),INT(U12)>=TODAY()),"Event in progress",IF(AND(O12="",R12<>"",INT(R12)>=TODAY()),"Registration due",IF(AND(O12="",U12<>"",INT(U12)>=TODAY()),"Deadline not published",IF(AND(O12<>"",Q12<>"",INT(Q12)>=TODAY()),"Camera-ready due",IF(AND(O12<>"",R12<>"",INT(R12)>=TODAY()),"Registration due",IF(AND(U12<>"",INT(U12)>=TODAY()),"Submissions closed - event ahead","Expired")))))))) -> Open | Z12: Not stated | AA12: Not published on the site | AB12: https://2027.fedcsis.org/ | AC12: Website | AD12: Not published on the site | AE12: 46269 | AF12: Dates confirmed: paper 14.05.2027, notification 28.06.2027, final paper 15.07.2027, early-registration discount ends 31.07.2027. FURTHER MILESTONES the tracker did not hold: position-paper submission 11.06.2027; thematic-session proposals 01.12.2026; summer-school proposals 01.03.2027; industrial-track proposals 25.06.2027. Event 12-15.09.2027, Gdynia, Poland. Fees still read TBA on the conference-fees page, and no submission-system URL, page limit or contact e-mail is published yet - only a generic /contact form. Proceedings in the Annals of Computer Science and Information Systems; IEEE catalogue number TBA. | AG12: 44732
A13: 12 | B13: MoMLeT&DS | C13: 2027 | D13: — | E13: Modern Machine Learning Technologies and Data Science | F13: Conference + Workshop | G13: High | H13: =IF($G13="High",1,IF($G13="Mediocre",2,3)) -> 1 | I13: CEUR.org | J13: CEUR-WS.org; Scopus, DBLP, Google Scholar | K13: Not published | O13: 46521 | P13: 46532 | Q13: 46537 | S13: 07 Jun 2027 | T13: 46545 | U13: 46545 | V13: Not stated - online event; run inside the "Mathematics. Information Technologies. Education" framework. Co-organised by the Leiden Institute of Advanced Computer Science (Netherlands), University of Jyvaskyla (Finland), Lviv Polytechnic National University, University Institute of Lisbon (Portugal), De Montfort University (UK), Politechnika Slaska (Poland) and Ivano-Frankivsk NTU of Oil and Gas | W13: Online (Zoom) | X13: =IF(O13="","",INT(O13)-TODAY()) -> 252 | Y13: =IF($G13="Finished","Expired",IF(AND(O13<>"",INT(O13)>=TODAY()),IF(INT(O13)-TODAY()<=30,"Open - closing soon","Open"),IF(AND(T13<>"",U13<>"",INT(T13)<=TODAY(),INT(U13)>=TODAY()),"Event in progress",IF(AND(O13="",R13<>"",INT(R13)>=TODAY()),"Registration due",IF(AND(O13="",U13<>"",INT(U13)>=TODAY()),"Deadline not published",IF(AND(O13<>"",Q13<>"",INT(Q13)>=TODAY()),"Camera-ready due",IF(AND(O13<>"",R13<>"",INT(R13)>=TODAY()),"Registration due",IF(AND(U13<>"",INT(U13)>=TODAY()),"Submissions closed - event ahead","Expired")))))))) -> Open | Z13: Not stated | AA13: Regular papers at least 10 pages | AB13: https://momlet.in.ua/important-dates/ | AC13: Website; EasyChair | AD13: momlet.in.ua@gmail.com; dmytro.h.dosyn@lpnu.ua | AE13: 46269 | AF13: Dates confirmed on /important-dates/: paper 14.05.2027, acceptance 25.05.2027, camera-ready 30.05.2027, workshop 07.06.2027. FILLED IN from /about-momlet/, which the previous pass did not read: FORMAT is "expected on-line participation using Zoom platform" (was "Not stated"); INDEXING is CEUR-WS.org with Scopus, DBLP and Google Scholar (was "Not stated"); PAPER LENGTH at least 10 pages; and two contact addresses. The Travel and Venue page is still empty, consistent with an online event. No fee published. | AG13: 44281
A14: 13 | B14: AI4Cyber | C14: 2026 | D14: — | E14: Workshop on Artificial Intelligence for Cybersecurity (AIC) | F14: Workshop | G14: High | H14: =IF($G14="High",1,IF($G14="Mediocre",2,3)) -> 1 | I14: CEUR.org | J14: CEUR-WS planned | K14: Not published | O14: 46272 | P14: 46275 | R14: 46272 | S14: 24–25 Sep 2026 | T14: 46289 | U14: 46290 | V14: University of the National Education Commission, Krakow, Poland (inside SMICS-2026) | W14: On-site | X14: =IF(O14="","",INT(O14)-TODAY()) -> 3 | Y14: =IF($G14="Finished","Expired",IF(AND(O14<>"",INT(O14)>=TODAY()),IF(INT(O14)-TODAY()<=30,"Open - closing soon","Open"),IF(AND(T14<>"",U14<>"",INT(T14)<=TODAY(),INT(U14)>=TODAY()),"Event in progress",IF(AND(O14="",R14<>"",INT(R14)>=TODAY()),"Registration due",IF(AND(O14="",U14<>"",INT(U14)>=TODAY()),"Deadline not published",IF(AND(O14<>"",Q14<>"",INT(Q14)>=TODAY()),"Camera-ready due",IF(AND(O14<>"",R14<>"",INT(R14)>=TODAY()),"Registration due",IF(AND(U14<>"",INT(U14)>=TODAY()),"Submissions closed - event ahead","Expired")))))))) -> Open - closing soon | Z14: Microsoft CMT (cmt3.research.microsoft.com/SMICS2026), subject area "AI for Cybersecurity" | AA14: More than 9 A4 pages; CEUR-WS ODT (LibreOffice) or LaTeX template, Libertinus font required, Word/Microsoft365 strongly discouraged; the FIRST author must have at least 5 papers indexed in DBLP; three files with fixed names - PDF, source, and a hand-signed scanned Author Agreement (NTP or TP variant) | AB14: https://smics.lnu.edu.ua/ | AC14: Website | AD14: ai_smics@lnu.edu.ua (workshop); smics@lnu.edu.ua (conference) | AE14: 46269 | AF14: OPEN - 3 days to the 07.09.2026 deadline. Dates FILLED IN from /en/dates, which the previous pass missed: 07.09.2026 is the "Deadline for Submission of Registration Forms - registration form submission closes for abstracts and workshop papers", so it is the SUBMISSION deadline as well as the registration deadline; notification of paper acceptance 10.09.2026; formal invitations and schedule guidelines 15.09.2026; conference days 24-25.09.2026. FORMAT CORRECTED from "Not stated" to on-site presentations at the University of the National Education Commission in Krakow. Nine-plus co-organisers across Ukraine, Poland, Sweden and the USA; 3 main tracks, 3 working languages; registration form forms.gle/wxu2zhuXg4vcPUCk8. No fee published. The workshop's official name on the site is "Artificial Intelligence for Cybersecurity (AIC)". ADDED its own paper specification and its own contact address, ai_smics@lnu.edu.ua. No prior CEUR volume was found, so this looks like a first edition - treat the scope as provisional. | AG14: 46269
A15: 14 | B15: SMICS | C15: 2026 | D15: — | E15: International Conference “Security of Modern Information and Communication Systems” | F15: Conference | G15: High | H15: =IF($G15="High",1,IF($G15="Mediocre",2,3)) -> 1 | I15: CEUR.org | J15: Two CEUR-WS workshop volumes planned | K15: Not published | O15: 46272 | P15: 46275 | R15: 46272 | S15: 24–25 Sep 2026 | T15: 46289 | U15: 46290 | V15: University of the National Education Commission, Krakow, Poland | W15: On-site | X15: =IF(O15="","",INT(O15)-TODAY()) -> 3 | Y15: =IF($G15="Finished","Expired",IF(AND(O15<>"",INT(O15)>=TODAY()),IF(INT(O15)-TODAY()<=30,"Open - closing soon","Open"),IF(AND(T15<>"",U15<>"",INT(T15)<=TODAY(),INT(U15)>=TODAY()),"Event in progress",IF(AND(O15="",R15<>"",INT(R15)>=TODAY()),"Registration due",IF(AND(O15="",U15<>"",INT(U15)>=TODAY()),"Deadline not published",IF(AND(O15<>"",Q15<>"",INT(Q15)>=TODAY()),"Camera-ready due",IF(AND(O15<>"",R15<>"",INT(R15)>=TODAY()),"Registration due",IF(AND(U15<>"",INT(U15)>=TODAY()),"Submissions closed - event ahead","Expired")))))))) -> Open - closing soon | Z15: E-mail for conference abstracts; Microsoft CMT (cmt3.research.microsoft.com/SMICS2026) for the two CEUR-WS workshops | AA15: Conference abstracts exactly 3-5 full A4 pages, LibreOffice ODT template with the Libertinus font, proper English, not edited by the organisers; max 2 abstracts per author and max 5 authors per paper; self-citation must not exceed 30% of references; mandatory sections - problem statement, novelty against known work, proposed solution, conclusions | AB15: https://smics.lnu.edu.ua/ | AC15: Website; Registration; CMT | AD15: smics@lnu.edu.ua; ai_smics@lnu.edu.ua (AI workshop); crypt_smics@lnu.edu.ua (cryptology workshop) | AE15: 46269 | AF15: OPEN - 3 days to the 07.09.2026 deadline. Dates FILLED IN from /en/dates, which the previous pass missed: 07.09.2026 is the "Deadline for Submission of Registration Forms - registration form submission closes for abstracts and workshop papers", so it is the SUBMISSION deadline as well as the registration deadline; notification of paper acceptance 10.09.2026; formal invitations and schedule guidelines 15.09.2026; conference days 24-25.09.2026. FORMAT CORRECTED from "Not stated" to on-site presentations at the University of the National Education Commission in Krakow. Nine-plus co-organisers across Ukraine, Poland, Sweden and the USA; 3 main tracks, 3 working languages; registration form forms.gle/wxu2zhuXg4vcPUCk8. No fee published. ADDED the main-proceedings abstract specification (3-5 A4 pages, ODT template, authorship and self-citation caps), which the previous pass left blank, and both workshop contact addresses. The two CEUR-WS workshops are "Artificial Intelligence for Cybersecurity" and "Cryptology and Data Security". Organised by the Department of Cybersecurity, Ivan Franko National University of Lviv. | AG15: 46269
A16: 15 | B16: WCDS | C16: 2026 | D16: — | E16: Workshop on Cryptology and Data Security (CDS) | F16: Workshop | G16: High | H16: =IF($G16="High",1,IF($G16="Mediocre",2,3)) -> 1 | I16: CEUR.org | J16: CEUR-WS planned for 2026; 2025 edition is Vol-4191 | K16: Not published | O16: 46272 | P16: 46275 | R16: 46272 | S16: 24–25 Sep 2026 | T16: 46289 | U16: 46290 | V16: University of the National Education Commission, Krakow, Poland (inside SMICS-2026) | W16: On-site | X16: =IF(O16="","",INT(O16)-TODAY()) -> 3 | Y16: =IF($G16="Finished","Expired",IF(AND(O16<>"",INT(O16)>=TODAY()),IF(INT(O16)-TODAY()<=30,"Open - closing soon","Open"),IF(AND(T16<>"",U16<>"",INT(T16)<=TODAY(),INT(U16)>=TODAY()),"Event in progress",IF(AND(O16="",R16<>"",INT(R16)>=TODAY()),"Registration due",IF(AND(O16="",U16<>"",INT(U16)>=TODAY()),"Deadline not published",IF(AND(O16<>"",Q16<>"",INT(Q16)>=TODAY()),"Camera-ready due",IF(AND(O16<>"",R16<>"",INT(R16)>=TODAY()),"Registration due",IF(AND(U16<>"",INT(U16)>=TODAY()),"Submissions closed - event ahead","Expired")))))))) -> Open - closing soon | Z16: Microsoft CMT (cmt3.research.microsoft.com/SMICS2026), subject area "Cryptology and Data Security" | AA16: More than 9 A4 pages; CEUR-WS ODT (LibreOffice) or LaTeX template, Libertinus font required, Word/Microsoft365 strongly discouraged; the FIRST author must have at least 5 papers indexed in DBLP; three files with fixed names - PDF, source, and a hand-signed scanned Author Agreement (NTP or TP variant) | AB16: https://smics.lnu.edu.ua/ | AC16: Website; CEUR volume | AD16: crypt_smics@lnu.edu.ua (workshop); smics@lnu.edu.ua (conference) | AE16: 46269 | AF16: OPEN - 3 days to the 07.09.2026 deadline. Dates FILLED IN from /en/dates, which the previous pass missed: 07.09.2026 is the "Deadline for Submission of Registration Forms - registration form submission closes for abstracts and workshop papers", so it is the SUBMISSION deadline as well as the registration deadline; notification of paper acceptance 10.09.2026; formal invitations and schedule guidelines 15.09.2026; conference days 24-25.09.2026. FORMAT CORRECTED from "Not stated" to on-site presentations at the University of the National Education Commission in Krakow. Nine-plus co-organisers across Ukraine, Poland, Sweden and the USA; 3 main tracks, 3 working languages; registration form forms.gle/wxu2zhuXg4vcPUCk8. No fee published. On the 2026 site the workshop is styled "Cryptology and Data Security (CDS)"; the acronym WCDS kept here is the one CEUR used for the 2025 edition (Vol-4191, co-located with SMICS 2025, Lviv, 16-18.10.2025, edited by Petro Venherskyi, Serhii Yevseiev, Oleg Gutik, Valeriy Trushevskyy and Mykhailo Viachalo of Ivan Franko NU of Lviv). ADDED its own paper specification and its own contact address, crypt_smics@lnu.edu.ua. | AG16: 46269
A17: 16 | B17: ICTERI | C17: 2026 | D17: 21st | E17: 21st International Conference on ICT in Education, Research and Industrial Applications | F17: Conference + Workshop | G17: Mediocre | H17: =IF($G17="High",1,IF($G17="Mediocre",2,3)) -> 2 | I17: Springer.org | J17: Springer CCIS; indexed by DBLP, EI-Compendex, Mathematical Reviews, SCImago and Scopus | K17: Free — "ICTERI 2026 does not charge any conference fee" | L17: 0 | M17: — | N17: 46132 | O17: 46160 | P17: 46202 | Q17: 46265 | R17: 46265 | S17: 15–18 Sep 2026 | T17: 46280 | U17: 46283 | V17: Yuriy Fedkovych Chernivtsi National University, Chernivtsi, Ukraine | W17: Hybrid | X17: =IF(O17="","",INT(O17)-TODAY()) -> -109 | Y17: =IF($G17="Finished","Expired",IF(AND(O17<>"",INT(O17)>=TODAY()),IF(INT(O17)-TODAY()<=30,"Open - closing soon","Open"),IF(AND(T17<>"",U17<>"",INT(T17)<=TODAY(),INT(U17)>=TODAY()),"Event in progress",IF(AND(O17="",R17<>"",INT(R17)>=TODAY()),"Registration due",IF(AND(O17="",U17<>"",INT(U17)>=TODAY()),"Deadline not published",IF(AND(O17<>"",Q17<>"",INT(Q17)>=TODAY()),"Camera-ready due",IF(AND(O17<>"",R17<>"",INT(R17)>=TODAY()),"Registration due",IF(AND(U17<>"",INT(U17)>=TODAY()),"Submissions closed - event ahead","Expired")))))))) -> Submissions closed - event ahead | Z17: Not stated | AA17: Not published on the site | AB17: https://icteri.org/icteri-2026/important-dates/ | AC17: Website | AD17: Not published on the site | AE17: 46269 | AF17: EVENT STARTS IN 11 DAYS. Dates re-confirmed on /important-dates/: abstract 20.04.2026, paper 04.05.2026 extended to 18.05.2026, notification 29.06.2026, camera-ready AND registration 31.08.2026, event 15-18.09.2026. ALSO on the page: workshop proposals 09.03.2026 with notification 16.03.2026. All deadlines are Anywhere-on-Earth (23:59 Hawaii). VENUE made specific - the host is Yuriy Fedkovych Chernivtsi National University. INDEXING corrected from "Springer CCIS (2025 approval pending)" to what the site actually claims: Springer CCIS indexed by DBLP, EI-Compendex, Mathematical Reviews, SCImago and Scopus. Free: "ICTERI 2026 does not charge any conference fee." Hybrid, with a stated preference for physical attendance and virtual participation by negotiation. No submission-system URL, page limit or contact e-mail is published. | AG17: 44294
A18: 17 | B18: KhPIW | C18: 2026 | D18: 7th | E18: IEEE 7th KhPI Week on Advanced Technology | F18: Conference | G18: Mediocre | H18: =IF($G18="High",1,IF($G18="Mediocre",2,3)) -> 2 | I18: IEEE.org | J18: IEEE; ISSN 3064-9560 (print), 3064-9579 (online), IEEE Conference Record #61439 | K18: Online/hybrid 250 EUR IEEE member, 300 EUR non-member, 150 EUR IEEE student, 200 EUR student non-member (VAT incl.); DISCOUNTS UP TO 95% for participants from Ukraine where foreign authors are 50% or fewer | L18: 150 | M18: EUR | O18: 46188 | P18: 46251 | Q18: 46264 | R18: 46285 | S18: 05–09 Oct 2026 | T18: 46300 | U18: 46304 | V18: National Technical University "Kharkiv Polytechnic Institute" (NTU "KhPI"), Kharkiv, Ukraine | W18: Online / hybrid | X18: =IF(O18="","",INT(O18)-TODAY()) -> -81 | Y18: =IF($G18="Finished","Expired",IF(AND(O18<>"",INT(O18)>=TODAY()),IF(INT(O18)-TODAY()<=30,"Open - closing soon","Open"),IF(AND(T18<>"",U18<>"",INT(T18)<=TODAY(),INT(U18)>=TODAY()),"Event in progress",IF(AND(O18="",R18<>"",INT(R18)>=TODAY()),"Registration due",IF(AND(O18="",U18<>"",INT(U18)>=TODAY()),"Deadline not published",IF(AND(O18<>"",Q18<>"",INT(Q18)>=TODAY()),"Camera-ready due",IF(AND(O18<>"",R18<>"",INT(R18)>=TODAY()),"Registration due",IF(AND(U18<>"",INT(U18)>=TODAY()),"Submissions closed - event ahead","Expired")))))))) -> Registration due | Z18: Not stated | AA18: Max 3 papers per author; +50% fee for a second paper, +75% for a third | AB18: https://khpiweek.ieee.org.ua/ | AC18: Website | AD18: Not published on the site | AE18: 46269 | AF18: REGISTRATION DEADLINE ADDED - 16 days out: the site's dates block gives "Final Payment Fees 20.09.2026", which the previous pass left blank. Other dates confirmed: paper 15.06.2026, acceptance 17.08.2026, final revision 30.08.2026; the conference programme is announced 07.09.2026; event 05-09.10.2026 at NTU "KhPI", Kharkiv. Fees 150-300 EUR with discounts up to 95% for participants from Ukraine where foreign authors are 50% or fewer; cashless payment only, no refunds; students and IEEE members must show proof. Proceedings ISSN 3064-9560 (print) / 3064-9579 (online), IEEE Conference Record #61439. No submission-system URL or contact e-mail is published on the site. | AG18: 44730
A19: 18 | B19: IS | C19: 2026 | D19: 13th | E19: IEEE 13th International Conference on Intelligent Systems | F19: Conference | G19: Mediocre | H19: =IF($G19="High",1,IF($G19="Mediocre",2,3)) -> 2 | I19: IEEE.org | J19: IEEE Xplore Digital Library; Scopus; Clarivate Web of Science | K19: Early (to 15 Aug) / late: IEEE members 400/450 EUR, non-members 450/500 EUR, students 300/350 EUR | L19: 300 | M19: EUR | O19: 46208 | P19: 46234 | Q19: 46244 | R19: 46269 | S19: 03–05 Sep 2026 | T19: 46268 | U19: 46270 | V19: Hotel Cherno More, Boulevard Slivnitsa 33, Varna, Bulgaria | W19: Hybrid | X19: =IF(O19="","",INT(O19)-TODAY()) -> -61 | Y19: =IF($G19="Finished","Expired",IF(AND(O19<>"",INT(O19)>=TODAY()),IF(INT(O19)-TODAY()<=30,"Open - closing soon","Open"),IF(AND(T19<>"",U19<>"",INT(T19)<=TODAY(),INT(U19)>=TODAY()),"Event in progress",IF(AND(O19="",R19<>"",INT(R19)>=TODAY()),"Registration due",IF(AND(O19="",U19<>"",INT(U19)>=TODAY()),"Deadline not published",IF(AND(O19<>"",Q19<>"",INT(Q19)>=TODAY()),"Camera-ready due",IF(AND(O19<>"",R19<>"",INT(R19)>=TODAY()),"Registration due",IF(AND(U19<>"",INT(U19)>=TODAY()),"Submissions closed - event ahead","Expired")))))))) -> Event in progress | Z19: EasyChair (easychair.org/conferences/?conf=is26) | AA19: 8 pages standard, IEEE two-column conference template, English, PDF only; EUR 50 per excess page; EUR 100 discount on a second paper by the same author | AB19: https://ieee-is-2026.blockchain2.uni-plovdiv.net/ | AC19: Website | AD19: ieee-is@bas.bg | AE19: 46269 | AF19: EVENT RUNNING NOW (03-05.09.2026). The news log confirms every extension: submission 08.06 to 22.06 to 05.07.2026; notification 20.07 to 31.07.2026; camera-ready 10.08.2026; early registration 03.08 to 07.08 to 15.08.2026. REGISTRATION DEADLINE CORRECTED from 25.08.2026: late registration closes 25.08.2026 for ONLINE participants but 04.09.2026 for in-person participants, so the last date is 04.09.2026 - today. MP4 uploads followed the same split (25.08 online, 04.09 in person). ADDED the EasyChair route, the 8-page IEEE two-column specification with the 50 EUR excess-page charge and the 100 EUR second-paper discount, the contact address, the full venue address and Web of Science to the indexing line. Fees: early/late IEEE 400/450 EUR, non-members 450/500 EUR, students 300/350 EUR, with the early/late line drawn at 15.08.2026. | AG19: 45345
A20: 19 | B20: ADT-ISMDDC | C20: 2026 | D20: — | E20: International Scientific and Practical Workshop “Advanced Digital Technologies: Intelligent Systems, Modeling, and Data-Driven Control” | F20: Workshop | G20: Mediocre | H20: =IF($G20="High",1,IF($G20="Mediocre",2,3)) -> 2 | I20: CEUR.org | J20: Scopus and DBLP; selected papers expanded into a collective monograph with ISBN, DOI, UDC and BBK | K20: Free — "Participation ... is free of charge" | L20: 0 | M20: — | O20: 46218 | P20: 46275 | R20: 46218 | S20: 22–24 Sep 2026 | T20: 46287 | U20: 46289 | V20: Odesa Polytechnic National University, Shevchenko ave. 1, 65044 Odesa, Ukraine (co-located with ICST-2026) | W20: Not stated | X20: =IF(O20="","",INT(O20)-TODAY()) -> -51 | Y20: =IF($G20="Finished","Expired",IF(AND(O20<>"",INT(O20)>=TODAY()),IF(INT(O20)-TODAY()<=30,"Open - closing soon","Open"),IF(AND(T20<>"",U20<>"",INT(T20)<=TODAY(),INT(U20)>=TODAY()),"Event in progress",IF(AND(O20="",R20<>"",INT(R20)>=TODAY()),"Registration due",IF(AND(O20="",U20<>"",INT(U20)>=TODAY()),"Deadline not published",IF(AND(O20<>"",Q20<>"",INT(Q20)>=TODAY()),"Camera-ready due",IF(AND(O20<>"",R20<>"",INT(R20)>=TODAY()),"Registration due",IF(AND(U20<>"",INT(U20)>=TODAY()),"Submissions closed - event ahead","Expired")))))))) -> Submissions closed - event ahead | Z20: EasyChair (easychair.org/cfp/adtismddc2026) plus a Google Forms registration form | AA20: CEUR article 10-15 pages in the new one-column CEUR ODT format; max 4 authors, at least one holding a PhD/DrSc with at least 4 DBLP-indexed papers | AB20: https://icst-conf.com/ | AC20: Website; EasyChair | AD20: icst_nuop@ukr.net; 126.ist.onpu@gmail.com; +38 (048) 705-85-69 (Chesnova Natalia Igorivna, business days 10:00-14:00) | AE20: 46269 | AF20: SUBMISSIONS CLOSED, EVENT AHEAD (18 days). Dates confirmed on the ICST-ODESA-2026 pages: applications and articles both 15.07.2026, preliminary acceptance with reviewer comments 30.08.2026, final acceptance 10.09.2026, event 22-24.09.2026. FURTHER MILESTONES now recorded: thesis-abstract submission 30.08.2026 (also the theses payment date), monograph applications close 20.09.2026 and monograph articles 30.09.2026 (also the monograph payment date). ADDED the paper specification (the workshop publishes through the same CEUR route as ICST: 10-15 pages, one-column CEUR ODT, max 4 authors with a qualified first author), the full venue address and the contact block - all three were blank. Participation in the workshop is free of charge. Selected papers are expanded into a collective monograph with ISBN, DOI, UDC and BBK. | AG20: 46269
A21: 20 | B21: ICST | C21: 2026 | D21: XIV | E21: Information Control Systems and Technologies | F21: Conference | G21: Mediocre | H21: =IF($G21="High",1,IF($G21="Mediocre",2,3)) -> 2 | I21: CEUR.org | J21: CEUR (Aachen, ISSN 1613-0073), Scopus and DBLP | K21: Free — participation in ICST-2026 is free of charge. Optional printed editions (Ukraine / abroad): electronic thesis 190 UAH / 35 USD, paper thesis 300 UAH / 70 USD, paper monograph 950 UAH | L21: 0 | M21: — | O21: 46218 | P21: 46275 | R21: 46218 | S21: 22–24 Sep 2026 | T21: 46287 | U21: 46289 | V21: Odesa Polytechnic National University, Shevchenko ave. 1, 65044 Odesa, Ukraine | W21: Not stated | X21: =IF(O21="","",INT(O21)-TODAY()) -> -51 | Y21: =IF($G21="Finished","Expired",IF(AND(O21<>"",INT(O21)>=TODAY()),IF(INT(O21)-TODAY()<=30,"Open - closing soon","Open"),IF(AND(T21<>"",U21<>"",INT(T21)<=TODAY(),INT(U21)>=TODAY()),"Event in progress",IF(AND(O21="",R21<>"",INT(R21)>=TODAY()),"Registration due",IF(AND(O21="",U21<>"",INT(U21)>=TODAY()),"Deadline not published",IF(AND(O21<>"",Q21<>"",INT(Q21)>=TODAY()),"Camera-ready due",IF(AND(O21<>"",R21<>"",INT(R21)>=TODAY()),"Registration due",IF(AND(U21<>"",INT(U21)>=TODAY()),"Submissions closed - event ahead","Expired")))))))) -> Submissions closed - event ahead | Z21: EasyChair (easychair.org/cfp/adtismddc2026) plus a Google Forms registration form | AA21: CEUR article 10-15 pages in the new one-column CEUR ODT format, max 4 authors with at least one holding a PhD/DrSc and at least 4 DBLP-indexed papers; thesis abstract 1-3 full A4 pages, Times New Roman 14pt, 1.5 line spacing; monograph article 16-24 pages, Times New Roman 12pt, 1.5 line spacing | AB21: https://icst-conf.com/ | AC21: Website; EasyChair | AD21: icst_nuop@ukr.net; 126.ist.onpu@gmail.com; +38 (048) 705-85-69 (Chesnova Natalia Igorivna, business days 10:00-14:00) | AE21: 46269 | AF21: SUBMISSIONS CLOSED, EVENT AHEAD (18 days). Dates confirmed on the ICST-ODESA-2026 pages: applications and articles both 15.07.2026, preliminary acceptance with reviewer comments 30.08.2026, final acceptance 10.09.2026, event 22-24.09.2026. FURTHER MILESTONES now recorded: thesis-abstract submission 30.08.2026 (also the theses payment date), monograph applications close 20.09.2026 and monograph articles 30.09.2026 (also the monograph payment date). ADDED the full venue address and the contact block, and extended the paper specification with the monograph track (16-24 pages, TNR 12pt). Costs confirmed: participation free; optional printed editions Ukraine/abroad - electronic thesis 190 UAH / 35 USD, paper thesis 300 UAH / 70 USD, paper monograph 950 UAH. Proceedings in CEUR (Aachen, ISSN 1613-0073), Scopus and DBLP. XIV edition. | AG21: 44730
A22: 21 | B22: XAI.it | C22: 2026 | D22: — | E22: Italian Workshop on Explainable AI, Generative and Agentic Systems: Trust, Transparency and Human Oversight | F22: Workshop | G22: Mediocre | H22: =IF($G22="High",1,IF($G22="Mediocre",2,3)) -> 2 | I22: CEUR.org | J22: CEUR AIxIA series; selected papers invited to Intelligenza Artificiale (IOS Press) | K22: Not published | O22: 46230 | P22: 46258 | Q22: 46279 | S22: 08–09 Oct 2026 | T22: 46303 | U22: 46304 | V22: Perugia, Italy - co-located with AI*IA 2026, the 24th International Conference of the Italian Association for Artificial Intelligence | W22: Not stated | X22: =IF(O22="","",INT(O22)-TODAY()) -> -39 | Y22: =IF($G22="Finished","Expired",IF(AND(O22<>"",INT(O22)>=TODAY()),IF(INT(O22)-TODAY()<=30,"Open - closing soon","Open"),IF(AND(T22<>"",U22<>"",INT(T22)<=TODAY(),INT(U22)>=TODAY()),"Event in progress",IF(AND(O22="",R22<>"",INT(R22)>=TODAY()),"Registration due",IF(AND(O22="",U22<>"",INT(U22)>=TODAY()),"Deadline not published",IF(AND(O22<>"",Q22<>"",INT(Q22)>=TODAY()),"Camera-ready due",IF(AND(O22<>"",R22<>"",INT(R22)>=TODAY()),"Registration due",IF(AND(U22<>"",INT(U22)>=TODAY()),"Submissions closed - event ahead","Expired")))))))) -> Camera-ready due | Z22: EasyChair (easychair.org/conferences/?conf=xaiit2026) | AA22: Regular papers 7-12 pages plus references; short and position papers 4-6 pages plus references; one-column CEUR-WS format | AB22: https://xai-it.github.io/call.html | AC22: Website; EasyChair | AD22: marco.polignano@uniba.it | AE22: 46269 | AF22: SUBMISSIONS CLOSED, EVENT AHEAD (34 days). Dates confirmed: paper 27.07.2026, notification to authors 24.08.2026, camera-ready 14.09.2026; event 08-09.10.2026. ADDED the EasyChair submission URL, the page limits and the contact address, and named the host conference - AI*IA 2026, the 24th conference of the Italian Association for AI, in Perugia. Published in the AIxIA series of CEUR-WS; best papers invited to "Intelligenza Artificiale" (IOS Press), indexed in Scopus and the Emerging Sources Citation Index. No registration deadline or fee published. | AG22: 45620
A23: 22 | B23: MCEME | C23: 2026 | D23: III | E23: III International Scientific and Theoretical Conference “Modeling and Computer Engineering in Mechanical Engineering: Theory, Practice, and Innovation” | F23: Workshop | G23: Mediocre | H23: =IF($G23="High",1,IF($G23="Mediocre",2,3)) -> 2 | I23: Academic Journal | J23: Papers are directed to the Lviv Polytechnic journal "Ukrainian Journal of Mechanical Engineering and Materials Science" and the interdepartmental collection "Automation of Industrial Processes in Mechanical Engineering and Instrumentation"; all publications go through double peer review | K23: Free — "There is no registration fee for participation in the conference" | L23: 0 | M23: — | O23: 46234 | Q23: 46254 | S23: 07–12 Sep 2026 (opening 08 Sep, 10:00) | T23: 46272 | U23: 46277 | V23: Lviv Polytechnic National University, 12 S. Bandera Street, Lviv 79013, Ukraine | W23: Hybrid | X23: =IF(O23="","",INT(O23)-TODAY()) -> -35 | Y23: =IF($G23="Finished","Expired",IF(AND(O23<>"",INT(O23)>=TODAY()),IF(INT(O23)-TODAY()<=30,"Open - closing soon","Open"),IF(AND(T23<>"",U23<>"",INT(T23)<=TODAY(),INT(U23)>=TODAY()),"Event in progress",IF(AND(O23="",R23<>"",INT(R23)>=TODAY()),"Registration due",IF(AND(O23="",U23<>"",INT(U23)>=TODAY()),"Deadline not published",IF(AND(O23<>"",Q23<>"",INT(Q23)>=TODAY()),"Camera-ready due",IF(AND(O23<>"",R23<>"",INT(R23)>=TODAY()),"Registration due",IF(AND(U23<>"",INT(U23)>=TODAY()),"Submissions closed - event ahead","Expired")))))))) -> Submissions closed - event ahead | Z23: Not stated | AA23: Not published on the site | AB23: https://science.lpnu.ua/mceme-2026 | AC23: Website | AD23: vasyl.t.dmytriv@lpnu.ua; +38(032)2582155, +380503724275 (chair Vasyl Dmytriv, Department of Design Machine and Automotive Engineering) | AE23: 46269 | AF23: EVENT RUNNING NOW (07-12.09.2026). Dates confirmed verbatim: 31.07.2026 18:00 applications and full text of report materials; 20.08.2026 18:00 full version of the article; 08.09.2026 10:00 opening and plenary session. Venue confirmed as Lviv Polytechnic National University, 12 S. Bandera Street, Lviv 79013 (organising committee at 1 Prof. Street, building 14). No registration fee, hotel requests by 20.08.2026. PUBLISHER CORRECTED from "Springer.org": the 2026 site routes papers to two Lviv Polytechnic outlets - the "Ukrainian Journal of Mechanical Engineering and Materials Science" and "Automation of Industrial Processes in Mechanical Engineering and Instrumentation" - with double peer review, and mentions no Springer volume. ADDED the chair's contact block. Working languages Ukrainian and English. No notification date is published. | AG23: 44728
A24: 23 | B24: ITTAP | C24: 2026 | D24: 6th | E24: The 6th International Conference on Information Technologies: Theoretical and Applied Problems | F24: Conference + Workshop | G24: Mediocre | H24: =IF($G24="High",1,IF($G24="Mediocre",2,3)) -> 2 | I24: CEUR.org | J24: DBLP and Scopus (planned) | K24: Free — remote participation and publication in the proceedings are free of charge | L24: 0 | M24: — | O24: 46237 | P24: 46275 | Q24: 46280 | S24: 19–21 Oct 2026 | T24: 46314 | U24: 46316 | V24: Ternopil Ivan Puluj National Technical University, Ternopil, Ukraine | W24: Hybrid (remote participation available) | X24: =IF(O24="","",INT(O24)-TODAY()) -> -32 | Y24: =IF($G24="Finished","Expired",IF(AND(O24<>"",INT(O24)>=TODAY()),IF(INT(O24)-TODAY()<=30,"Open - closing soon","Open"),IF(AND(T24<>"",U24<>"",INT(T24)<=TODAY(),INT(U24)>=TODAY()),"Event in progress",IF(AND(O24="",R24<>"",INT(R24)>=TODAY()),"Registration due",IF(AND(O24="",U24<>"",INT(U24)>=TODAY()),"Deadline not published",IF(AND(O24<>"",Q24<>"",INT(Q24)>=TODAY()),"Camera-ready due",IF(AND(O24<>"",R24<>"",INT(R24)>=TODAY()),"Registration due",IF(AND(U24<>"",INT(U24)>=TODAY()),"Submissions closed - event ahead","Expired")))))))) -> Camera-ready due | Z24: Microsoft CMT (cmt3.research.microsoft.com/ITTAP2026) | AA24: Regular papers 10-20 pages or short papers 5-9 pages, English; CEUR-ART template in .odt; max 5 co-authors; max 2 submissions per author (Programme and Organising Committee members 1) | AB24: https://ittap.tntu.edu.ua/ | AC24: Website; Submission; CMT | AD24: ittapua@gmail.com | AE24: 46269 | AF24: SUBMISSIONS CLOSED, EVENT AHEAD (45 days). The site shows each date twice, original and extended: paper 27.07 extended to 03.08.2026; REVISED PAPER 24.08 extended to 31.08.2026 (a milestone the tracker did not hold); notification 03.09 extended to 10.09.2026; camera-ready 15.09.2026; event 19-21.10.2026. SUBMISSION SYSTEM CORRECTED: the previous pass recorded EasyChair, but the site names Microsoft CMT at cmt3.research.microsoft.com/ITTAP2026. FORMAT refined to hybrid, and the contact e-mail and author limits added. Remote participation and publication are free; special journal publication fees apply only to papers selected for a journal. Three independent workshops run inside the conference. Proceedings to CEUR-WS, indexed in DBLP and Scopus. | AG24: 44406
A25: 24 | B25: HC@AIxIA | C25: 2026 | D25: 5th | E25: 5th International AIxIA Workshop on Artificial Intelligence for Healthcare | F25: Conference + Workshop | G25: Mediocre | H25: =IF($G25="High",1,IF($G25="Mediocre",2,3)) -> 2 | I25: Not yet announced | J25: Publication venue TBA - the organisers state it "will be unveiled later"; a journal special issue or a post-proceedings volume is possible | K25: Authors must register for AIxIA 2026 (workshop fee not published separately) | N25: 46238 | O25: 46238 | P25: 46261 | Q25: 46280 | R25: 46269 | S25: 06–09 Oct 2026 | T25: 46301 | U25: 46304 | V25: Perugia, Italy | W25: In-person (oral presentations; includes the annual AIxIA Healthcare Working Group meeting) | X25: =IF(O25="","",INT(O25)-TODAY()) -> -31 | Y25: =IF($G25="Finished","Expired",IF(AND(O25<>"",INT(O25)>=TODAY()),IF(INT(O25)-TODAY()<=30,"Open - closing soon","Open"),IF(AND(T25<>"",U25<>"",INT(T25)<=TODAY(),INT(U25)>=TODAY()),"Event in progress",IF(AND(O25="",R25<>"",INT(R25)>=TODAY()),"Registration due",IF(AND(O25="",U25<>"",INT(U25)>=TODAY()),"Deadline not published",IF(AND(O25<>"",Q25<>"",INT(Q25)>=TODAY()),"Camera-ready due",IF(AND(O25<>"",R25<>"",INT(R25)>=TODAY()),"Registration due",IF(AND(U25<>"",INT(U25)>=TODAY()),"Submissions closed - event ahead","Expired")))))))) -> Camera-ready due | Z25: ChairingTool (chairingtool.com/conferences/aixia2026/main-track?role=author) | AA25: Full papers max 15 pages including bibliography; short, position and discussion papers max 7 pages; no page limit for non-original contributions; Springer LNCS formatting guidelines | AB25: https://hcaixia2026.unical.it/call-for-papers/ | AC25: Website | AD25: hc-aixia@googlegroups.com | AE25: 46269 | AF25: SUBMISSIONS CLOSED, EVENT AHEAD (32 days). THREE DATES ADDED that the previous pass left blank: notification of acceptance 27.08.2026, camera-ready 15.09.2026, early registration 04.09.2026 - today. Abstract and paper submission both 04.08.2026 (extended) confirmed. PUBLISHER CORRECTED from "CEUR.org": the call says only "The publication venue for the proceedings is TBA, and will be unveiled later", with a journal special issue or post-proceedings volume as possibilities, so CEUR is not confirmed for this edition. Submission runs through ChairingTool on the AIxIA 2026 main track, not a CEUR-style system. ADDED the LNCS formatting note and the mailing-list contact. 5th edition, Perugia, Italy, inside AIxIA 2026, 06-09.10.2026; authors must register for AIxIA 2026 and no separate workshop fee is published. | AG25: 45609
